2021-02-12 00:40:29,539 INFO MASTER DATA GENERATOR START
2021-02-12 00:40:29,539 INFO attempting to process master data
2021-02-12 00:40:29,542 INFO master data generator finished and exiting
2021-02-12 00:42:34,881 INFO MASTER DATA GENERATOR START
2021-02-12 00:42:34,881 INFO attempting to process master data
2021-02-12 00:42:34,882 INFO master data generator finished and exiting
2021-02-12 00:44:51,604 INFO MASTER DATA GENERATOR START
2021-02-12 00:44:51,604 INFO attempting to process master data
2021-02-12 00:44:51,605 INFO master data generator finished and exiting
2021-02-12 00:48:29,096 INFO MASTER DATA GENERATOR START
2021-02-12 00:48:29,096 INFO attempting to process master data
2021-02-12 00:48:29,101 INFO master data generator finished and exiting
2021-02-12 00:50:16,971 INFO MASTER DATA GENERATOR START
2021-02-12 00:50:16,973 INFO attempting to process master data
2021-02-12 00:50:20,944 INFO master data generator finished and exiting
2021-02-14 18:47:49,888 INFO MASTER DATA GENERATOR START
2021-02-14 18:47:49,903 INFO attempting to process master data
2021-02-14 18:48:45,275 INFO master data generator finished and exiting
2021-02-15 12:09:08,452 INFO MASTER DATA GENERATOR START
2021-02-15 12:09:08,453 INFO attempting to process master data
2021-02-15 12:09:08,575 ERROR unable to process participant TEST_HIT_FAR_LANE
Traceback (most recent call last):
  File "MasterDataGenerator.py", line 141, in save_master_data
    p_sessions)
  File "MasterDataGenerator.py", line 116, in _get_non_practice_trials_output
    spss_output_list.extend(rdp.get_spss_output())
  File "/Users/nalsadi/Documents/vrts/vrtsAWS/vrtsAWS/RawDataParser.py", line 175, in get_spss_output
    self.parseTrials()
  File "/Users/nalsadi/Documents/vrts/vrtsAWS/vrtsAWS/RawDataParser.py", line 70, in wrapper
    res = func(*arg)
  File "/Users/nalsadi/Documents/vrts/vrtsAWS/vrtsAWS/RawDataParser.py", line 208, in parseTrials
    trialData = TrialDetail(raw_data, self.__carBoundingBoxDict)
  File "/Users/nalsadi/Documents/vrts/vrtsAWS/vrtsAWS/TrialDetail.py", line 28, in __init__
    self._participant = TrialParticipant(self._trial_data[TrialData.PARTICIPANT_POSITION], self._trial_data[TrialData.PARTICIPANT_ORIENTATION])
  File "/Users/nalsadi/Documents/vrts/vrtsAWS/vrtsAWS/TrialParticipant.py", line 41, in __init__
    self._repair_velocity_data_with_savitzky_golay_filter()
  File "/Users/nalsadi/Documents/vrts/vrtsAWS/vrtsAWS/TrialParticipant.py", line 134, in _repair_velocity_data_with_savitzky_golay_filter
    filtered_velocities = scipy.signal.savgol_filter(sorted_velocities, window_length, polynomial_order)
AttributeError: 'module' object has no attribute 'savgol_filter'
2021-02-15 12:09:08,716 ERROR unable to process participant TEST_HIT_NEAR_LANE
Traceback (most recent call last):
  File "MasterDataGenerator.py", line 141, in save_master_data
    p_sessions)
  File "MasterDataGenerator.py", line 116, in _get_non_practice_trials_output
    spss_output_list.extend(rdp.get_spss_output())
  File "/Users/nalsadi/Documents/vrts/vrtsAWS/vrtsAWS/RawDataParser.py", line 175, in get_spss_output
    self.parseTrials()
  File "/Users/nalsadi/Documents/vrts/vrtsAWS/vrtsAWS/RawDataParser.py", line 70, in wrapper
    res = func(*arg)
  File "/Users/nalsadi/Documents/vrts/vrtsAWS/vrtsAWS/RawDataParser.py", line 208, in parseTrials
    trialData = TrialDetail(raw_data, self.__carBoundingBoxDict)
  File "/Users/nalsadi/Documents/vrts/vrtsAWS/vrtsAWS/TrialDetail.py", line 28, in __init__
    self._participant = TrialParticipant(self._trial_data[TrialData.PARTICIPANT_POSITION], self._trial_data[TrialData.PARTICIPANT_ORIENTATION])
  File "/Users/nalsadi/Documents/vrts/vrtsAWS/vrtsAWS/TrialParticipant.py", line 41, in __init__
    self._repair_velocity_data_with_savitzky_golay_filter()
  File "/Users/nalsadi/Documents/vrts/vrtsAWS/vrtsAWS/TrialParticipant.py", line 134, in _repair_velocity_data_with_savitzky_golay_filter
    filtered_velocities = scipy.signal.savgol_filter(sorted_velocities, window_length, polynomial_order)
AttributeError: 'module' object has no attribute 'savgol_filter'
2021-02-15 12:09:08,985 ERROR unable to process participant TEST_HIT_FAR_LANE_NOT_IN_MIDDLE
Traceback (most recent call last):
  File "MasterDataGenerator.py", line 141, in save_master_data
    p_sessions)
  File "MasterDataGenerator.py", line 116, in _get_non_practice_trials_output
    spss_output_list.extend(rdp.get_spss_output())
  File "/Users/nalsadi/Documents/vrts/vrtsAWS/vrtsAWS/RawDataParser.py", line 175, in get_spss_output
    self.parseTrials()
  File "/Users/nalsadi/Documents/vrts/vrtsAWS/vrtsAWS/RawDataParser.py", line 70, in wrapper
    res = func(*arg)
  File "/Users/nalsadi/Documents/vrts/vrtsAWS/vrtsAWS/RawDataParser.py", line 208, in parseTrials
    trialData = TrialDetail(raw_data, self.__carBoundingBoxDict)
  File "/Users/nalsadi/Documents/vrts/vrtsAWS/vrtsAWS/TrialDetail.py", line 28, in __init__
    self._participant = TrialParticipant(self._trial_data[TrialData.PARTICIPANT_POSITION], self._trial_data[TrialData.PARTICIPANT_ORIENTATION])
  File "/Users/nalsadi/Documents/vrts/vrtsAWS/vrtsAWS/TrialParticipant.py", line 41, in __init__
    self._repair_velocity_data_with_savitzky_golay_filter()
  File "/Users/nalsadi/Documents/vrts/vrtsAWS/vrtsAWS/TrialParticipant.py", line 134, in _repair_velocity_data_with_savitzky_golay_filter
    filtered_velocities = scipy.signal.savgol_filter(sorted_velocities, window_length, polynomial_order)
AttributeError: 'module' object has no attribute 'savgol_filter'
2021-02-15 12:09:08,995 INFO master data generator finished and exiting
